Workbook
Name category: Table10[Category]
Name Name: Table1[Name List]
Name Slicer_Month: #N/A
Name Slicer_OverDue_Aleart: #N/A
Name Slicer_PIC: #N/A
Name Slicer_Status: #N/A
Name Slicer_Type: #N/A
Name Slicer_WW: #N/A
Name Slicer_WW2: #N/A
Name task_name: Refer!$C$5:$C$45

Sheet Dashboard Monthly
K44: Other Task List | O44: Overdue List
K46: TASK | L46: Qty | O46: WW | P46: Type | Q46: TASK | R46: PRODUCT | S46: Target Date
K47: {=IF(_xlfn._xlws.SORT(Pivot!$C$18:$D$32,2,-1)=0,"",(_xlfn._xlws.SORT(Pivot!$C$18:$D$32,2,-1)))} -> Training | L47: 20 | O47: {=IF(Pivot!$AK$5:$AO$31=0,"",Pivot!$AK$5:$AO$31)}
K48: Visit Exhibition | L48: 5
K49: Create standard document | L49: 2
K50: 5S meeting | L50: 2
K51: Interview candidate new member | L51: 1
K52: Support register document | L52: 1

Sheet Dashboard Weekly
Q2: ้
K25: t
K44: Other Task List | O44: Overdue List
K46: TASK | L46: Qty | O46: WW | P46: Type | Q46: TASK | R46: PRODUCT | S46: Target Date
K47: {=IF(_xlfn._xlws.SORT(Pivot!$C$18:$D$32,2,-1)=0,"",(_xlfn._xlws.SORT(Pivot!$C$18:$D$32,2,-1)))} -> Training | L47: 20 | O47: {=IF(Pivot!$AK$5:$AO$31=0,"",Pivot!$AK$5:$AO$31)}
K48: Visit Exhibition | L48: 5
K49: Create standard document | L49: 2
K50: 5S meeting | L50: 2
K51: Interview candidate new member | L51: 1
K52: Support register document | L52: 1

Sheet Schedule2026
A2: NPI INTEGRATION FRONTED TASK SCHEDULE | H2: =TODAY() -> 46213 | K2: ="Week "&WEEKNUM(TODAY(),1) -> Week 28 | O2: 46023
F3: % Type | G3: % Closed | O3: =O2+(U4*7)-10 -> 46202
E4: DFM Mold | F4: =COUNTIF(Table6[Type],E4)/COUNTA(Table6[Type]) -> 0.096096096 | G4: =COUNTIFS(Table6[Type],E4,Table6[Status],"Close")/COUNTIF(Table6[Type],E4) -> 1 | O4: Start Gantt Week: | U4: 27
E5: OTHER | F5: =COUNTIF(Table6[Type],E5)/COUNTA(Table6[Type]) -> 0.046546547 | G5: =COUNTIFS(Table6[Type],E5,Table6[Status],"Close")/COUNTIF(Table6[Type],E5) -> 1
E6: NPI | F6: =COUNTIF(Table6[Type],E6)/COUNTA(Table6[Type]) -> 0.28078078 | G6: =COUNTIFS(Table6[Type],E6,Table6[Status],"Close")/COUNTIF(Table6[Type],E6) -> 0.99465241 | O6: Edit the week number to update the display
E7: Part DFM | F7: =COUNTIF(Table6[Type],E7)/COUNTA(Table6[Type]) -> 0.022522523 | G7: =COUNTIFS(Table6[Type],E7,Table6[Status],"Close")/COUNTIF(Table6[Type],E7) -> 1
E8: MEETING | F8: =COUNTIF(Table6[Type],E8)/COUNTA(Table6[Type]) -> 0.11261261 | G8: =COUNTIFS(Table6[Type],E8,Table6[Status],"Close")/COUNTIF(Table6[Type],E8) -> 1 | N8: =TEXT(P10,"MMMM") -> July | U8: =TEXT(W10,"MMMM") -> July | AB8: =TEXT(AD10,"MMMM") -> July | AI8: =TEXT(AK10,"MMMM") -> July
E9: RFQ | F9: =COUNTIF(Table6[Type],E9)/COUNTA(Table6[Type]) -> 0.1006006 | G9: =COUNTIFS(Table6[Type],E9,Table6[Status],"Close")/COUNTIF(Table6[Type],E9) -> 0.97014925 | N9: ="WW "&WEEKNUM(N10) -> WW 27 | U9: ="WW "&WEEKNUM(U10) -> WW 28 | AB9: ="WW "&WEEKNUM(AB10) -> WW 29 | AI9: ="WW "&WEEKNUM(AI10) -> WW 30
E10: PROJECT | F10: =COUNTIF(Table6[Type],E10)/COUNTA(Table6[Type]) -> 0.010510511 | G10: =COUNTIFS(Table6[Type],E10,Table6[Status],"Close")/COUNTIF(Table6[Type],E10) -> 0.85714286 | N10: =O3 -> 46202 | O10: =N10+1 -> 46203 | P10: =O10+1 -> 46204 | Q10: =P10+1 -> 46205 | R10: =Q10+1 -> 46206 | S10: =R10+1 -> 46207 | T10: =S10+1 -> 46208 | U10: =T10+1 -> 46209 | V10: =U10+1 -> 46210 | ... AO10: =AN10+1 -> 46229
E11: Packing | F11: =COUNTIF(Table6[Type],E11)/COUNTA(Table6[Type]) -> 0.2987988 | N11: =TEXT(N10,"ddd") -> Mon | O11: =TEXT(O10,"ddd") -> Tue | P11: =TEXT(P10,"ddd") -> Wed | Q11: =TEXT(Q10,"ddd") -> Thu | R11: =TEXT(R10,"ddd") -> Fri | S11: =TEXT(S10,"ddd") -> Sat | T11: =TEXT(T10,"ddd") -> Sun | U11: =TEXT(U10,"ddd") -> Mon | ... AO11: =TEXT(AO10,"ddd") -> Sun
A12: WW | B12: Month | C12: Type | D12: TASK | E12: PRODUCT/Description | F12: CUSTOMER | G12: PIC | H12: Start Date | I12: Target Date | J12: Finish Date | K12: Status | L12: OverDue Aleart | M12: Performace status | N12: Column1 | O12: Column12 | P12: Column13 | Q12: Column14 | R12: Column15 | S12: Column16 | T12: Column17 | U12: Column18 | V12: Column19 | W12: Column110 | X12: Column111 | Y12: Column112 | Z12: Column113 | AA12: Column114 | AB12: Column115 | AC12: Column116 | AD12: Column117 | AE12: Column118 | AF12: Column119 | AG12: Column120 | AH12: Column121 | AI12: Column122 | AJ12: Column123 | AK12: Column124 | AL12: Column125 | AM12: Column126 | AN12: Column127 | AO12: Column128
A13: =WEEKNUM(Table6[[#This Row],[Start Date]]) -> 2 | B13: =TEXT(Table6[[#This Row],[Start Date]],"mmm") -> Jan | C13: =_xlfn.IFNA(INDEX(Refer!$B$5:$B$103,MATCH(Table6[[#This Row],[TASK]],Refer!$C$5:$C$103,0)),"") -> NPI | D13: NPI Technical support | E13: AMW 03457 Follow up customer comment about dimension outspec or not of part screen protection | F13: Numworks | G13: Thiti | H13: 46027 | I13: 46027 | J13: 46027 | K13: =IF(Table6[[#This Row],[Finish Date]]=0,"On process","Close") -> Close | L13: =IF(Table6[[#This Row],[Status]]="On process",IF($H$2>Table6[[#This Row],[Target Date]],"Overdue","On time"),"Closed") -> Closed | M13: {=_xlfn.IFS(Table6[[#This Row],[Finish Date]]=0,"",Table6[[#This Row],[Finish Date]]>Table6[[#This Row],[Target Date]],"Delay",Table6[[#This Row],[Finish Date]]<=Table6[[#This Row],[Target Date]],"On Time")} -> On Time
A14: =WEEKNUM(Table6[[#This Row],[Start Date]]) -> 2 | B14: =TEXT(Table6[[#This Row],[Start Date]],"mmm") -> Jan | C14: =_xlfn.IFNA(INDEX(Refer!$B$5:$B$103,MATCH(Table6[[#This Row],[TASK]],Refer!$C$5:$C$103,0)),"") -> NPI | D14: NPI Technical support | E14: Confirm drawing to SRC about area texture on logo of part BOX of JRI model | F14: JRI | G14: thiti | H14: 46028 | I14: 46028 | J14: 46028 | K14: =IF(Table6[[#This Row],[Finish Date]]=0,"On process","Close") -> Close | L14: =IF(Table6[[#This Row],[Status]]="On process",IF($H$2>Table6[[#This Row],[Target Date]],"Overdue","On time"),"Closed") -> Closed | M14: {=_xlfn.IFS(Table6[[#This Row],[Finish Date]]=0,"",Table6[[#This Row],[Finish Date]]>Table6[[#This Row],[Target Date]],"Delay",Table6[[#This Row],[Finish Date]]<=Table6[[#This Row],[Target Date]],"On Time")} -> On Time
A15: =WEEKNUM(Table6[[#This Row],[Start Date]]) -> 2 | B15: =TEXT(Table6[[#This Row],[Start Date]],"mmm") -> Jan | C15: =_xlfn.IFNA(INDEX(Refer!$B$5:$B$103,MATCH(Table6[[#This Row],[TASK]],Refer!$C$5:$C$103,0)),"") -> NPI | D15: NPI Technical support | E15: Support made 2D drawing printing detial of Numworks school Property project | F15: Numworks | G15: Thiti | H15: 46028 | I15: 46029 | J15: 46029 | K15: =IF(Table6[[#This Row],[Finish Date]]=0,"On process","Close") -> Close | L15: =IF(Table6[[#This Row],[Status]]="On process",IF($H$2>Table6[[#This Row],[Target Date]],"Overdue","On time"),"Closed") -> Closed | M15: {=_xlfn.IFS(Table6[[#This Row],[Finish Date]]=0,"",Table6[[#This Row],[Finish Date]]>Table6[[#This Row],[Target Date]],"Delay",Table6[[#This Row],[Finish Date]]<=Table6[[#This Row],[Target Date]],"On Time")} -> On Time
A16: =WEEKNUM(Table6[[#This Row],[Start Date]]) -> 2 | B16: =TEXT(Table6[[#This Row],[Start Date]],"mmm") -> Jan | C16: =_xlfn.IFNA(INDEX(Refer!$B$5:$B$103,MATCH(Table6[[#This Row],[TASK]],Refer!$C$5:$C$103,0)),"") -> NPI | D16: NPI Technical support | E16: AMW 03457 Support SRC review cost laser engraving JIG | F16: Numworks | G16: Thiti | H16: 46029 | I16: 46030 | J16: 46030 | K16: =IF(Table6[[#This Row],[Finish Date]]=0,"On process","Close") -> Close | L16: =IF(Table6[[#This Row],[Status]]="On process",IF($H$2>Table6[[#This Row],[Target Date]],"Overdue","On time"),"Closed") -> Closed | M16: {=_xlfn.IFS(Table6[[#This Row],[Finish Date]]=0,"",Table6[[#This Row],[Finish Date]]>Table6[[#This Row],[Target Date]],"Delay",Table6[[#This Row],[Finish Date]]<=Table6[[#This Row],[Target Date]],"On Time")} -> On Time
A17: =WEEKNUM(Table6[[#This Row],[Start Date]]) -> 2 | B17: =TEXT(Table6[[#This Row],[Start Date]],"mmm") -> Jan | C17: =_xlfn.IFNA(INDEX(Refer!$B$5:$B$103,MATCH(Table6[[#This Row],[TASK]],Refer!$C$5:$C$103,0)),"") -> NPI | D17: Review JIG concept | E17: AMW 03457 Review concept jig design for attached foam screen | F17: Numworks | G17: Thiti | H17: 46029 | I17: 46029 | J17: 46029 | K17: =IF(Table6[[#This Row],[Finish Date]]=0,"On process","Close") -> Close | L17: =IF(Table6[[#This Row],[Status]]="On process",IF($H$2>Table6[[#This Row],[Target Date]],"Overdue","On time"),"Closed") -> Closed | M17: {=_xlfn.IFS(Table6[[#This Row],[Finish Date]]=0,"",Table6[[#This Row],[Finish Date]]>Table6[[#This Row],[Target Date]],"Delay",Table6[[#This Row],[Finish Date]]<=Table6[[#This Row],[Target Date]],"On Time")} -> On Time
A18: =WEEKNUM(Table6[[#This Row],[Start Date]]) -> 2 | B18: =TEXT(Table6[[#This Row],[Start Date]],"mmm") -> Jan | C18: =_xlfn.IFNA(INDEX(Refer!$B$5:$B$103,MATCH(Table6[[#This Row],[TASK]],Refer!$C$5:$C$103,0)),"") -> MEETING | D18: Meeting | E18: AMW 03457 N0102 Numworks weekly progress | F18: Numworks | G18: Thiti | H18: 46030 | I18: 46030 | J18: 46030 | K18: =IF(Table6[[#This Row],[Finish Date]]=0,"On process","Close") -> Close | L18: =IF(Table6[[#This Row],[Status]]="On process",IF($H$2>Table6[[#This Row],[Target Date]],"Overdue","On time"),"Closed") -> Closed | M18: {=_xlfn.IFS(Table6[[#This Row],[Finish Date]]=0,"",Table6[[#This Row],[Finish Date]]>Table6[[#This Row],[Target Date]],"Delay",Table6[[#This Row],[Finish Date]]<=Table6[[#This Row],[Target Date]],"On Time")} -> On Time
A19: =WEEKNUM(Table6[[#This Row],[Start Date]]) -> 3 | B19: =TEXT(Table6[[#This Row],[Start Date]],"mmm") -> Jan | C19: =_xlfn.IFNA(INDEX(Refer!$B$5:$B$103,MATCH(Table6[[#This Row],[TASK]],Refer!$C$5:$C$103,0)),"") -> NPI | D19: NPI Technical support | E19: Confirm handmafe sample modify idea of Jointpile | F19: JRI | G19: Thiti | H19: 46034 | I19: 46034 | J19: 46034 | K19: =IF(Table6[[#This Row],[Finish Date]]=0,"On process","Close") -> Close | L19: =IF(Table6[[#This Row],[Status]]="On process",IF($H$2>Table6[[#This Row],[Target Date]],"Overdue","On time"),"Closed") -> Closed | M19: {=_xlfn.IFS(Table6[[#This Row],[Finish Date]]=0,"",Table6[[#This Row],[Finish Date]]>Table6[[#This Row],[Target Date]],"Delay",Table6[[#This Row],[Finish Date]]<=Table6[[#This Row],[Target Date]],"On Time")} -> On Time
A20: =WEEKNUM(Table6[[#This Row],[Start Date]]) -> 3 | B20: =TEXT(Table6[[#This Row],[Start Date]],"mmm") -> Jan | C20: =_xlfn.IFNA(INDEX(Refer!$B$5:$B$103,MATCH(Table6[[#This Row],[TASK]],Refer!$C$5:$C$103,0)),"") -> NPI | D20: NPI Technical support | E20: Study overmold concept for new JRI project | F20: JRI | G20: Thiti | H20: 46034 | I20: 46034 | J20: 46034 | K20: =IF(Table6[[#This Row],[Finish Date]]=0,"On process","Close") -> Close | L20: =IF(Table6[[#This Row],[Status]]="On process",IF($H$2>Table6[[#This Row],[Target Date]],"Overdue","On time"),"Closed") -> Closed | M20: {=_xlfn.IFS(Table6[[#This Row],[Finish Date]]=0,"",Table6[[#This Row],[Finish Date]]>Table6[[#This Row],[Target Date]],"Delay",Table6[[#This Row],[Finish Date]]<=Table6[[#This Row],[Target Date]],"On Time")} -> On Time
A21: =WEEKNUM(Table6[[#This Row],[Start Date]]) -> 3 | B21: =TEXT(Table6[[#This Row],[Start Date]],"mmm") -> Jan | C21: =_xlfn.IFNA(INDEX(Refer!$B$5:$B$103,MATCH(Table6[[#This Row],[TASK]],Refer!$C$5:$C$103,0)),"") -> NPI | D21: NPI Technical support | E21: Visit new supplier Tontec | G21: Thiti | H21: 46035 | I21: 46035 | J21: 46035 | K21: =IF(Table6[[#This Row],[Finish Date]]=0,"On process","Close") -> Close | L21: =IF(Table6[[#This Row],[Status]]="On process",IF($H$2>Table6[[#This Row],[Target Date]],"Overdue","On time"),"Closed") -> Closed | M21: {=_xlfn.IFS(Table6[[#This Row],[Finish Date]]=0,"",Table6[[#This Row],[Finish Date]]>Table6[[#This Row],[Target Date]],"Delay",Table6[[#This Row],[Finish Date]]<=Table6[[#This Row],[Target Date]],"On Time")} -> On Time
A22: =WEEKNUM(Table6[[#This Row],[Start Date]]) -> 3 | B22: =TEXT(Table6[[#This Row],[Start Date]],"mmm") -> Jan | C22: =_xlfn.IFNA(INDEX(Refer!$B$5:$B$103,MATCH(Table6[[#This Row],[TASK]],Refer!$C$5:$C$103,0)),"") -> NPI | D22: NPI Technical support | E22: Review modify cost for Laser Engraving base jig JRI | F22: JRI | G22: Thiti | H22: 46036 | I22: 46036 | J22: 46036 | K22: =IF(Table6[[#This Row],[Finish Date]]=0,"On process","Close") -> Close | L22: =IF(Table6[[#This Row],[Status]]="On process",IF($H$2>Table6[[#This Row],[Target Date]],"Overdue","On time"),"Closed") -> Closed | M22: {=_xlfn.IFS(Table6[[#This Row],[Finish Date]]=0,"",Table6[[#This Row],[Finish Date]]>Table6[[#This Row],[Target Date]],"Delay",Table6[[#This Row],[Finish Date]]<=Table6[[#This Row],[Target Date]],"On Time")} -> On Time
A23: =WEEKNUM(Table6[[#This Row],[Start Date]]) -> 3 | B23: =TEXT(Table6[[#This Row],[Start Date]],"mmm") -> Jan | C23: =_xlfn.IFNA(INDEX(Refer!$B$5:$B$103,MATCH(Table6[[#This Row],[TASK]],Refer!$C$5:$C$103,0)),"") -> NPI | D23: NPI Technical support | E23: AMW 03457 Review inspection report of NW ( 6 parts ) and judgement for using in assembly | F23: Numworks | G23: Thiti | H23: 46036 | I23: 46037 | J23: 46037 | K23: =IF(Table6[[#This Row],[Finish Date]]=0,"On process","Close") -> Close | L23: =IF(Table6[[#This Row],[Status]]="On process",IF($H$2>Table6[[#This Row],[Target Date]],"Overdue","On time"),"Closed") -> Closed | M23: {=_xlfn.IFS(Table6[[#This Row],[Finish Date]]=0,"",Table6[[#This Row],[Finish Date]]>Table6[[#This Row],[Target Date]],"Delay",Table6[[#This Row],[Finish Date]]<=Table6[[#This Row],[Target Date]],"On Time")} -> On Time
A24: =WEEKNUM(Table6[[#This Row],[Start Date]]) -> 3 | B24: =TEXT(Table6[[#This Row],[Start Date]],"mmm") -> Jan | C24: =_xlfn.IFNA(INDEX(Refer!$B$5:$B$103,MATCH(Table6[[#This Row],[TASK]],Refer!$C$5:$C$103,0)),"") -> MEETING | D24: Meeting | E24: JRI weekly meeting | F24: JRI | G24: Thiti | H24: 46036 | I24: 46036 | J24: 46036 | K24: =IF(Table6[[#This Row],[Finish Date]]=0,"On process","Close") -> Close | L24: =IF(Table6[[#This Row],[Status]]="On process",IF($H$2>Table6[[#This Row],[Target Date]],"Overdue","On time"),"Closed") -> Closed | M24: {=_xlfn.IFS(Table6[[#This Row],[Finish Date]]=0,"",Table6[[#This Row],[Finish Date]]>Table6[[#This Row],[Target Date]],"Delay",Table6[[#This Row],[Finish Date]]<=Table6[[#This Row],[Target Date]],"On Time")} -> On Time
A25: =WEEKNUM(Table6[[#This Row],[Start Date]]) -> 3 | B25: =TEXT(Table6[[#This Row],[Start Date]],"mmm") -> Jan | C25: =_xlfn.IFNA(INDEX(Refer!$B$5:$B$103,MATCH(Table6[[#This Row],[TASK]],Refer!$C$5:$C$103,0)),"") -> NPI | D25: NPI Technical support | E25: Confirm handmafe sample modify idea of Jointpile rev2 | F25: JRI | G25: Thiti | H25: 46038 | I25: 46038 | J25: 46038 | K25: =IF(Table6[[#This Row],[Finish Date]]=0,"On process","Close") -> Close | L25: =IF(Table6[[#This Row],[Status]]="On process",IF($H$2>Table6[[#This Row],[Target Date]],"Overdue","On time"),"Closed") -> Closed | M25: {=_xlfn.IFS(Table6[[#This Row],[Finish Date]]=0,"",Table6[[#This Row],[Finish Date]]>Table6[[#This Row],[Target Date]],"Delay",Table6[[#This Row],[Finish Date]]<=Table6[[#This Row],[Target Date]],"On Time")} -> On Time
A26: =WEEKNUM(Table6[[#This Row],[Start Date]]) -> 4 | B26: =TEXT(Table6[[#This Row],[Start Date]],"mmm") -> Jan | C26: =_xlfn.IFNA(INDEX(Refer!$B$5:$B$103,MATCH(Table6[[#This Row],[TASK]],Refer!$C$5:$C$103,0)),"") -> Part DFM | D26: Review internal DFM | E26: AMW 03667 Review New JRI Digital Sensor mode | F26: JRI | G26: Thiti | H26: 46041 | I26: 46042 | J26: 46042 | K26: =IF(Table6[[#This Row],[Finish Date]]=0,"On process","Close") -> Close | L26: =IF(Table6[[#This Row],[Status]]="On process",IF($H$2>Table6[[#This Row],[Target Date]],"Overdue","On time"),"Closed") -> Closed | M26: {=_xlfn.IFS(Table6[[#This Row],[Finish Date]]=0,"",Table6[[#This Row],[Finish Date]]>Table6[[#This Row],[Target Date]],"Delay",Table6[[#This Row],[Finish Date]]<=Table6[[#This Row],[Target Date]],"On Time")} -> On Time
A27: =WEEKNUM(Table6[[#This Row],[Start Date]]) -> 4 | B27: =TEXT(Table6[[#This Row],[Start Date]],"mmm") -> Jan | C27: =_xlfn.IFNA(INDEX(Refer!$B$5:$B$103,MATCH(Table6[[#This Row],[TASK]],Refer!$C$5:$C$103,0)),"") -> Part DFM | D27: Review internal DFM | E27: AMW 03668 Review New JRI Digital Sensor mode | F27: JRI | G27: Thiti | H27: 46041 | I27: 46042 | J27: 46042 | K27: =IF(Table6[[#This Row],[Finish Date]]=0,"On process","Close") -> Close | L27: =IF(Table6[[#This Row],[Status]]="On process",IF($H$2>Table6[[#This Row],[Target Date]],"Overdue","On time"),"Closed") -> Closed | M27: {=_xlfn.IFS(Table6[[#This Row],[Finish Date]]=0,"",Table6[[#This Row],[Finish Date]]>Table6[[#This Row],[Target Date]],"Delay",Table6[[#This Row],[Finish Date]]<=Table6[[#This Row],[Target Date]],"On Time")} -> On Time
A28: =WEEKNUM(Table6[[#This Row],[Start Date]]) -> 4 | B28: =TEXT(Table6[[#This Row],[Start Date]],"mmm") -> Jan | C28: =_xlfn.IFNA(INDEX(Refer!$B$5:$B$103,MATCH(Table6[[#This Row],[TASK]],Refer!$C$5:$C$103,0)),"") -> Part DFM | D28: Review internal DFM | E28: AMW 03669 Review New JRI Digital Sensor model | F28: JRI | G28: Thiti | H28: 46042 | I28: 46043 | J28: 46042 | K28: =IF(Table6[[#This Row],[Finish Date]]=0,"On process","Close") -> Close | L28: =IF(Table6[[#This Row],[Status]]="On process",IF($H$2>Table6[[#This Row],[Target Date]],"Overdue","On time"),"Closed") -> Closed | M28: {=_xlfn.IFS(Table6[[#This Row],[Finish Date]]=0,"",Table6[[#This Row],[Finish Date]]>Table6[[#This Row],[Target Date]],"Delay",Table6[[#This Row],[Finish Date]]<=Table6[[#This Row],[Target Date]],"On Time")} -> On Time
A29: =WEEKNUM(Table6[[#This Row],[Start Date]]) -> 4 | B29: =TEXT(Table6[[#This Row],[Start Date]],"mmm") -> Jan | C29: =_xlfn.IFNA(INDEX(Refer!$B$5:$B$103,MATCH(Table6[[#This Row],[TASK]],Refer!$C$5:$C$103,0)),"") -> Part DFM | D29: Review internal DFM | E29: AMW 036670 Review New JRI Digital Sensor model | F29: JRI | G29: Thiti | H29: 46042 | I29: 46043 | J29: 46042 | K29: =IF(Table6[[#This Row],[Finish Date]]=0,"On process","Close") -> Close | L29: =IF(Table6[[#This Row],[Status]]="On process",IF($H$2>Table6[[#This Row],[Target Date]],"Overdue","On time"),"Closed") -> Closed | M29: {=_xlfn.IFS(Table6[[#This Row],[Finish Date]]=0,"",Table6[[#This Row],[Finish Date]]>Table6[[#This Row],[Target Date]],"Delay",Table6[[#This Row],[Finish Date]]<=Table6[[#This Row],[Target Date]],"On Time")} -> On Time
A30: =WEEKNUM(Table6[[#This Row],[Start Date]]) -> 4 | B30: =TEXT(Table6[[#This Row],[Start Date]],"mmm") -> Jan | C30: =_xlfn.IFNA(INDEX(Refer!$B$5:$B$103,MATCH(Table6[[#This Row],[TASK]],Refer!$C$5:$C$103,0)),"") -> NPI | D30: Sample assembly Support | E30: AMW 03457 Numworks final sample assembly 12 pcs. (PCBA Assy with Plastic T2) | F30: Numworks | G30: Thiti | H30: 46045 | I30: 46045 | J30: 46045 | K30: =IF(Table6[[#This Row],[Finish Date]]=0,"On process","Close") -> Close | L30: =IF(Table6[[#This Row],[Status]]="On process",IF($H$2>Table6[[#This Row],[Target Date]],"Overdue","On time"),"Closed") -> Closed | M30: {=_xlfn.IFS(Table6[[#This Row],[Finish Date]]=0,"",Table6[[#This Row],[Finish Date]]>Table6[[#This Row],[Target Date]],"Delay",Table6[[#This Row],[Finish Date]]<=Table6[[#This Row],[Target Date]],"On Time")} -> On Time
A31: =WEEKNUM(Table6[[#This Row],[Start Date]]) -> 4 | B31: =TEXT(Table6[[#This Row],[Start Date]],"mmm") -> Jan | C31: =_xlfn.IFNA(INDEX(Refer!$B$5:$B$103,MATCH(Table6[[#This Row],[TASK]],Refer!$C$5:$C$103,0)),"") -> NPI | D31: NPI Technical support | E31: JRI Prepare modification report of JRI-Trapp | F31: JRI | G31: Thiti | H31: 46045 | I31: 46045 | J31: 46045 | K31: =IF(Table6[[#This Row],[Finish Date]]=0,"On process","Close") -> Close | L31: =IF(Table6[[#This Row],[Status]]="On process",IF($H$2>Table6[[#This Row],[Target Date]],"Overdue","On time"),"Closed") -> Closed | M31: {=_xlfn.IFS(Table6[[#This Row],[Finish Date]]=0,"",Table6[[#This Row],[Finish Date]]>Table6[[#This Row],[Target Date]],"Delay",Table6[[#This Row],[Finish Date]]<=Table6[[#This Row],[Target Date]],"On Time")} -> On Time
A32: =WEEKNUM(Table6[[#This Row],[Start Date]]) -> 5 | B32: =TEXT(Table6[[#This Row],[Start Date]],"mmm") -> Jan | C32: =_xlfn.IFNA(INDEX(Refer!$B$5:$B$103,MATCH(Table6[[#This Row],[TASK]],Refer!$C$5:$C$103,0)),"") -> MEETING | D32: Meeting | E32: JRI Weekly progress | F32: JRI | G32: Thiti | H32: 46048 | I32: 46048 | J32: 46048 | K32: =IF(Table6[[#This Row],[Finish Date]]=0,"On process","Close") -> Close | L32: =IF(Table6[[#This Row],[Status]]="On process",IF($H$2>Table6[[#This Row],[Target Date]],"Overdue","On time"),"Closed") -> Closed | M32: {=_xlfn.IFS(Table6[[#This Row],[Finish Date]]=0,"",Table6[[#This Row],[Finish Date]]>Table6[[#This Row],[Target Date]],"Delay",Table6[[#This Row],[Finish Date]]<=Table6[[#This Row],[Target Date]],"On Time")} -> On Time
A33: =WEEKNUM(Table6[[#This Row],[Start Date]]) -> 5 | B33: =TEXT(Table6[[#This Row],[Start Date]],"mmm") -> Jan | C33: =_xlfn.IFNA(INDEX(Refer!$B$5:$B$103,MATCH(Table6[[#This Row],[TASK]],Refer!$C$5:$C$103,0)),"") -> NPI | D33: NPI Technical support | E33: JRI GDS Review update drawing from customer and R&D | F33: JRI | G33: Thiti | H33: 46048 | I33: 46049 | J33: 46049 | K33: =IF(Table6[[#This Row],[Finish Date]]=0,"On process","Close") -> Close | L33: =IF(Table6[[#This Row],[Status]]="On process",IF($H$2>Table6[[#This Row],[Target Date]],"Overdue","On time"),"Closed") -> Closed | M33: {=_xlfn.IFS(Table6[[#This Row],[Finish Date]]=0,"",Table6[[#This Row],[Finish Date]]>Table6[[#This Row],[Target Date]],"Delay",Table6[[#This Row],[Finish Date]]<=Table6[[#This Row],[Target Date]],"On Time")} -> On Time
... A36: =WEEKNUM(Table6[[#This Row],[Start Date]]) -> 5 | B36: =TEXT(Table6[[#This Row],[Start Date]],"mmm") -> Jan | C36: =_xlfn.IFNA(INDEX(Refer!$B$5:$B$103,MATCH(Table6[[#This Row],[TASK]],Refer!$C$5:$C$103,0)),"") -> NPI | D36: NPI Technical support | E36: AMW 03210,03211 Support eng. trial part ring for fine solution to improve ring not lock. | F36: Enersys | G36: Thiti | H36: 46050 | I36: 46050 | J36: 46050 | K36: =IF(Table6[[#This Row],[Finish Date]]=0,"On process","Close") -> Close | L36: =IF(Table6[[#This Row],[Status]]="On process",IF($H$2>Table6[[#This Row],[Target Date]],"Overdue","On time"),"Closed") -> Closed | M36: {=_xlfn.IFS(Table6[[#This Row],[Finish Date]]=0,"",Table6[[#This Row],[Finish Date]]>Table6[[#This Row],[Target Date]],"Delay",Table6[[#This Row],[Finish Date]]<=Table6[[#This Row],[Target Date]],"On Time")} -> On Time
A37: =WEEKNUM(Table6[[#This Row],[Start Date]]) -> 5 | B37: =TEXT(Table6[[#This Row],[Start Date]],"mmm") -> Jan | C37: =_xlfn.IFNA(INDEX(Refer!$B$5:$B$103,MATCH(Table6[[#This Row],[TASK]],Refer!$C$5:$C$103,0)),"") -> NPI | D37: NPI Technical support | E37: JRI waiting customer confirm modification report of JRI-Trapp | G37: Thiti | H37: 46051 | I37: 46051 | J37: 46051 | K37: =IF(Table6[[#This Row],[Finish Date]]=0,"On process","Close") -> Close | L37: =IF(Table6[[#This Row],[Status]]="On process",IF($H$2>Table6[[#This Row],[Target Date]],"Overdue","On time"),"Closed") -> Closed | M37: {=_xlfn.IFS(Table6[[#This Row],[Finish Date]]=0,"",Table6[[#This Row],[Finish Date]]>Table6[[#This Row],[Target Date]],"Delay",Table6[[#This Row],[Finish Date]]<=Table6[[#This Row],[Target Date]],"On Time")} -> On Time
A38: =WEEKNUM(Table6[[#This Row],[Start Date]]) -> 5 | B38: =TEXT(Table6[[#This Row],[Start Date]],"mmm") -> Jan | C38: =_xlfn.IFNA(INDEX(Refer!$B$5:$B$103,MATCH(Table6[[#This Row],[TASK]],Refer!$C$5:$C$103,0)),"") -> MEETING | D38: Meeting | E38: Numworks weekly meeting | F38: Numworks | G38: Thiti | H38: 46051 | I38: 46051 | J38: 46051 | K38: =IF(Table6[[#This Row],[Finish Date]]=0,"On process","Close") -> Close | L38: =IF(Table6[[#This Row],[Status]]="On process",IF($H$2>Table6[[#This Row],[Target Date]],"Overdue","On time"),"Closed") -> Closed | M38: {=_xlfn.IFS(Table6[[#This Row],[Finish Date]]=0,"",Table6[[#This Row],[Finish Date]]>Table6[[#This Row],[Target Date]],"Delay",Table6[[#This Row],[Finish Date]]<=Table6[[#This Row],[Target Date]],"On Time")} -> On Time
A39: =WEEKNUM(Table6[[#This Row],[Start Date]]) -> 5 | B39: =TEXT(Table6[[#This Row],[Start Date]],"mmm") -> Jan | C39: =_xlfn.IFNA(INDEX(Refer!$B$5:$B$103,MATCH(Table6[[#This Row],[TASK]],Refer!$C$5:$C$103,0)),"") -> DFM Mold | D39: Review DFM MOLD and feed back | E39: AMW 03577 DFM mold meeting | F39: FONROCHE | G39: Thiti | H39: 46051 | I39: 46051 | J39: 46051 | K39: =IF(Table6[[#This Row],[Finish Date]]=0,"On process","Close") -> Close | L39: =IF(Table6[[#This Row],[Status]]="On process",IF($H$2>Table6[[#This Row],[Target Date]],"Overdue","On time"),"Closed") -> Closed | M39: {=_xlfn.IFS(Table6[[#This Row],[Finish Date]]=0,"",Table6[[#This Row],[Finish Date]]>Table6[[#This Row],[Target Date]],"Delay",Table6[[#This Row],[Finish Date]]<=Table6[[#This Row],[Target Date]],"On Time")} -> On Time
A40: =WEEKNUM(Table6[[#This Row],[Start Date]]) -> 5 | B40: =TEXT(Table6[[#This Row],[Start Date]],"mmm") -> Jan | C40: =_xlfn.IFNA(INDEX(Refer!$B$5:$B$103,MATCH(Table6[[#This Row],[TASK]],Refer!$C$5:$C$103,0)),"") -> NPI | D40: NPI Technical support | E40: JRI Request supplier addition sheet protect for ultrasonic weldding, follow up result. | F40: JRI | G40: Thiti | H40: 46052 | I40: 46052 | J40: 46052 | K40: =IF(Table6[[#This Row],[Finish Date]]=0,"On process","Close") -> Close | L40: =IF(Table6[[#This Row],[Status]]="On process",IF($H$2>Table6[[#This Row],[Target Date]],"Overdue","On time"),"Closed") -> Closed | M40: {=_xlfn.IFS(Table6[[#This Row],[Finish Date]]=0,"",Table6[[#This Row],[Finish Date]]>Table6[[#This Row],[Target Date]],"Delay",Table6[[#This Row],[Finish Date]]<=Table6[[#This Row],[Target Date]],"On Time")} -> On Time
A41: =WEEKNUM(Table6[[#This Row],[Start Date]]) -> 6 | B41: =TEXT(Table6[[#This Row],[Start Date]],"mmm") -> Feb | C41: =_xlfn.IFNA(INDEX(Refer!$B$5:$B$103,MATCH(Table6[[#This Row],[TASK]],Refer!$C$5:$C$103,0)),"") -> NPI | D41: NPI Technical support | E41: Go to supplier to discuss idea improve foam screen packing standard for MP | F41: Numworks | G41: Thiti | H41: 46055 | I41: 46055 | J41: 46055 | K41: =IF(Table6[[#This Row],[Finish Date]]=0,"On process","Close") -> Close | L41: =IF(Table6[[#This Row],[Status]]="On process",IF($H$2>Table6[[#This Row],[Target Date]],"Overdue","On time"),"Closed") -> Closed | M41: {=_xlfn.IFS(Table6[[#This Row],[Finish Date]]=0,"",Table6[[#This Row],[Finish Date]]>Table6[[#This Row],[Target Date]],"Delay",Table6[[#This Row],[Finish Date]]<=Table6[[#This Row],[Target Date]],"On Time")} -> On Time
A42: =WEEKNUM(Table6[[#This Row],[Start Date]]) -> 6 | B42: =TEXT(Table6[[#This Row],[Start Date]],"mmm") -> Feb | C42: =_xlfn.IFNA(INDEX(Refer!$B$5:$B$103,MATCH(Table6[[#This Row],[TASK]],Refer!$C$5:$C$103,0)),"") -> NPI | D42: NPI Technical support | E42: JRI, Support SRC review modify cost of trape | F42: JRI | G42: Thiti | H42: 46056 | I42: 46056 | J42: 46056 | K42: =IF(Table6[[#This Row],[Finish Date]]=0,"On process","Close") -> Close | L42: =IF(Table6[[#This Row],[Status]]="On process",IF($H$2>Table6[[#This Row],[Target Date]],"Overdue","On time"),"Closed") -> Closed | M42: {=_xlfn.IFS(Table6[[#This Row],[Finish Date]]=0,"",Table6[[#This Row],[Finish Date]]>Table6[[#This Row],[Target Date]],"Delay",Table6[[#This Row],[Finish Date]]<=Table6[[#This Row],[Target Date]],"On Time")} -> On Time
A43: =WEEKNUM(Table6[[#This Row],[Start Date]]) -> 6 | B43: =TEXT(Table6[[#This Row],[Start Date]],"mmm") -> Feb | C43: =_xlfn.IFNA(INDEX(Refer!$B$5:$B$103,MATCH(Table6[[#This Row],[TASK]],Refer!$C$5:$C$103,0)),"") -> OTHER | D43: Create standard document | E43: Make New part control sheet document for viper 6 bay | F43: Enersys | G43: Thiti | H43: 46057 | I43: 46057 | J43: 46057 | K43: =IF(Table6[[#This Row],[Finish Date]]=0,"On process","Close") -> Close | L43: =IF(Table6[[#This Row],[Status]]="On process",IF($H$2>Table6[[#This Row],[Target Date]],"Overdue","On time"),"Closed") -> Closed | M43: {=_xlfn.IFS(Table6[[#This Row],[Finish Date]]=0,"",Table6[[#This Row],[Finish Date]]>Table6[[#This Row],[Target Date]],"Delay",Table6[[#This Row],[Finish Date]]<=Table6[[#This Row],[Target Date]],"On Time")} -> On Time
...

Sheet Refer
B3: Category | C3: Column1
A4: Sort | B4: Category | C4: Task name | E4: Name List | G4: Category | I4: Sort | J4: Category
A5: =INDEX(Table11[Sort],MATCH(Table9[[#This Row],[Category]],Table11[Category],0)) -> 1 | B5: NPI | C5: Sample assembly Support | E5: Bunnarak | G5: RFQ | I5: 1 | J5: NPI | M5: Niran
A6: =INDEX(Table11[Sort],MATCH(Table9[[#This Row],[Category]],Table11[Category],0)) -> 1 | B6: NPI | C6: Pilot assembly Support | E6: Tae | G6: NPI | I6: 2 | J6: DFM Mold | M6: Tanawit | S6: ข
A7: =INDEX(Table11[Sort],MATCH(Table9[[#This Row],[Category]],Table11[Category],0)) -> 1 | B7: NPI | C7: PreSerise assembly Support | E7: Thiti | G7: DFM | I7: 3 | J7: Part DFM | M7: Somchai
A8: =INDEX(Table11[Sort],MATCH(Table9[[#This Row],[Category]],Table11[Category],0)) -> 1 | B8: NPI | C8: Trial tooling | E8: Nattachai | G8: OTHER | I8: 4 | J8: RFQ | M8: Vanassanan
A9: =INDEX(Table11[Sort],MATCH(Table9[[#This Row],[Category]],Table11[Category],0)) -> 1 | B9: NPI | C9: Quality Issue Analysis | E9: Chutiporn | G9: Internal DFM | I9: 5 | J9: PROJECT | M9: All
A10: =INDEX(Table11[Sort],MATCH(Table9[[#This Row],[Category]],Table11[Category],0)) -> 1 | B10: NPI | C10: NPI Technical support | E10: All | G10: PROJECT | I10: 6 | J10: MEETING
A11: =INDEX(Table11[Sort],MATCH(Table9[[#This Row],[Category]],Table11[Category],0)) -> 1 | B11: NPI | C11: Review OPL | G11: MEETING | I11: 7 | J11: OTHER
A12: =INDEX(Table11[Sort],MATCH(Table9[[#This Row],[Category]],Table11[Category],0)) -> 1 | B12: NPI | C12: Review JIG concept | G12: DFA | I12: 8 | J12: DFA
A13: =INDEX(Table11[Sort],MATCH(Table9[[#This Row],[Category]],Table11[Category],0)) -> 1 | B13: NPI | C13: Create drawing | I13: 9 | J13: PACKING
A14: =INDEX(Table11[Sort],MATCH(Table9[[#This Row],[Category]],Table11[Category],0)) -> 9 | B14: PACKING | C14: Design New Packaging
A15: =INDEX(Table11[Sort],MATCH(Table9[[#This Row],[Category]],Table11[Category],0)) -> 9 | B15: PACKING | C15: Support packing
A16: =INDEX(Table11[Sort],MATCH(Table9[[#This Row],[Category]],Table11[Category],0)) -> 2 | B16: DFM Mold | C16: Review DFM Part Drawing and feed back
A17: =INDEX(Table11[Sort],MATCH(Table9[[#This Row],[Category]],Table11[Category],0)) -> 2 | B17: DFM Mold | C17: Review DFM MOLD and feed back
A18: =INDEX(Table11[Sort],MATCH(Table9[[#This Row],[Category]],Table11[Category],0)) -> 2 | B18: DFM Mold | C18: DFM Feedback to Customer and waiting customer review
A19: =INDEX(Table11[Sort],MATCH(Table9[[#This Row],[Category]],Table11[Category],0)) -> 2 | B19: DFM Mold | C19: Review Revised Data and Final DFM Mold Approval
A20: =INDEX(Table11[Sort],MATCH(Table9[[#This Row],[Category]],Table11[Category],0)) -> 3 | B20: Part DFM | C20: Initial review custmer data for DFM
A21: =INDEX(Table11[Sort],MATCH(Table9[[#This Row],[Category]],Table11[Category],0)) -> 3 | B21: Part DFM | C21: Review internal DFM
A22: =INDEX(Table11[Sort],MATCH(Table9[[#This Row],[Category]],Table11[Category],0)) -> 3 | B22: Part DFM | C22: Review Revised Data and Final internal DFM Approval
A23: =INDEX(Table11[Sort],MATCH(Table9[[#This Row],[Category]],Table11[Category],0)) -> 3 | B23: Part DFM | C23: Review Part and Assembly level
A24: =INDEX(Table11[Sort],MATCH(Table9[[#This Row],[Category]],Table11[Category],0)) -> 3 | B24: Part DFM | C24: Confirm Q'ty for assembly event and time to assembly
A25: =INDEX(Table11[Sort],MATCH(Table9[[#This Row],[Category]],Table11[Category],0)) -> 4 | B25: RFQ | C25: RFQ
... A28: =INDEX(Table11[Sort],MATCH(Table9[[#This Row],[Category]],Table11[Category],0)) -> 9 | B28: PACKING | C28: Prepare customer label
A29: 9 | B29: PACKING | C29: Confirm packing
A30: =INDEX(Table11[Sort],MATCH(Table9[[#This Row],[Category]],Table11[Category],0)) -> 5 | B30: PROJECT | C30: Improve working process
A31: =INDEX(Table11[Sort],MATCH(Table9[[#This Row],[Category]],Table11[Category],0)) -> 1 | B31: NPI | C31: MP assembly support
A32: =INDEX(Table11[Sort],MATCH(Table9[[#This Row],[Category]],Table11[Category],0)) -> 1 | B32: NPI | C32: Checking part trial
A33: =INDEX(Table11[Sort],MATCH(Table9[[#This Row],[Category]],Table11[Category],0)) -> 6 | B33: MEETING | C33: Meeting
A34: =INDEX(Table11[Sort],MATCH(Table9[[#This Row],[Category]],Table11[Category],0)) -> 7 | B34: OTHER | C34: Training
A35: =INDEX(Table11[Sort],MATCH(Table9[[#This Row],[Category]],Table11[Category],0)) -> 7 | B35: OTHER | C35: Support register document
A36: =INDEX(Table11[Sort],MATCH(Table9[[#This Row],[Category]],Table11[Category],0)) -> 7 | B36: OTHER | C36: Process Improvement
A37: =INDEX(Table11[Sort],MATCH(Table9[[#This Row],[Category]],Table11[Category],0)) -> 7 | B37: OTHER | C37: Create standard document
A38: =INDEX(Table11[Sort],MATCH(Table9[[#This Row],[Category]],Table11[Category],0)) -> 7 | B38: OTHER | C38: Planing
A39: =INDEX(Table11[Sort],MATCH(Table9[[#This Row],[Category]],Table11[Category],0)) -> 7 | B39: OTHER | C39: Interview candidate new member
A40: =INDEX(Table11[Sort],MATCH(Table9[[#This Row],[Category]],Table11[Category],0)) -> 7 | B40: OTHER | C40: 5S meeting
A41: =INDEX(Table11[Sort],MATCH(Table9[[#This Row],[Category]],Table11[Category],0)) -> 7 | B41: OTHER | C41: Visit Exhibition
... A47: =INDEX(Table11[Sort],MATCH(Table9[[#This Row],[Category]],Table11[Category],0)) -> 7 | B47: OTHER | C47: Support adjust CAD data

Sheet Pivot monthly
B1: Ratio | G1: Pending task | U1: Close vs open | AB1: Overdue | AS1: Status | AT1: Close
AK2: OverDue Aleart | AL2: (หลายรายการ)
C3: ป้ายชื่อแถว | D3: Count of TASK | H3: Count of Status | I3: ป้ายชื่อคอลัมน์ | P3: sort | V3: Count of Status | X3: ป้ายชื่อคอลัมน์ | AC3: Count of OverDue Aleart | AE3: ป้ายชื่อคอลัมน์ | AS3: Count of Performace status | AU3: ป้ายชื่อคอลัมน์ | AZ3: total | BA3: =GETPIVOTDATA("Performace",$AS$3) -> 659
C4: NPI | D4: 187 | H4: ป้ายชื่อแถว | I4: Close | J4: On process | L4: Type | M4: Close | N4: On process | P4: Type | Q4: Close | R4: On Process | V4: ป้ายชื่อแถว | W4: WW | X4: Close | Y4: On process | Z4: (ว่าง) | AC4: ป้ายชื่อแถว | AD4: WW | AE4: Overdue | AF4: Closed | AG4: On time | AH4: (ว่าง) | AK4: ป้ายชื่อแถว | AL4: Type | AM4: TASK | AN4: Target Date | AS4: ป้ายชื่อแถว | AT4: WW | AU4: On Time | AV4: ผลรวมทั้งหมด | AZ4: ontime | BA4: =GETPIVOTDATA("Performace",$AS$3,"Performace","On Time") -> 659 | BB4: =BA4/BA3 -> 1
C5: MEETING | D5: 75 | H5: MEETING | I5: 75 | L5: RFQ | M5: =IFERROR(VLOOKUP(L5,$H$5:$J$13,2,FALSE),0) -> 65 | N5: =IFERROR(VLOOKUP(L5,$H$5:$J$13,3,FALSE),0) -> 2 | P5: {=_xlfn._xlws.SORT(L5:N12,3,-1)} -> RFQ | Q5: 65 | R5: 2 | V5: May | W5: 19 | X5: 14 | AC5: May | AF5: 109 | AS5: May | AU5: 109 | AV5: 109 | AZ5: delay | BA5: =IFERROR(GETPIVOTDATA("Performace",$AS$3,"Performace","Delay"),0) -> 0 | BB5: =BA5/BA3 -> 0
C6: OTHER | D6: 31 | H6: NPI | I6: 186 | J6: 1 | L6: NPI | M6: =IFERROR(VLOOKUP(L6,$H$5:$J$13,2,FALSE),0) -> 186 | N6: =IFERROR(VLOOKUP(L6,$H$5:$J$13,3,FALSE),0) -> 1 | P6: NPI | Q6: 186 | R6: 1 | V6: May | W6: 20 | X6: 28 | AC6: Jun | AF6: 133 | AS6: Jun | AU6: 132 | AV6: 132
C7: DFA | D7: 20 | H7: OTHER | I7: 31 | L7: DFM | M7: =IFERROR(VLOOKUP(L7,$H$5:$J$13,2,FALSE),0) -> 0 | N7: =IFERROR(VLOOKUP(L7,$H$5:$J$13,3,FALSE),0) -> 0 | P7: PROJECT | Q7: 6 | R7: 1 | V7: May | W7: 21 | X7: 39 | AC7: Jul | AD7: 27 | AF7: 15 | AS7: Jul | AT7: 27 | AU7: 15 | AV7: 15
C8: PROJECT | D8: 7 | H8: DFA | I8: 20 | L8: OTHER | M8: =IFERROR(VLOOKUP(L8,$H$5:$J$13,2,FALSE),0) -> 31 | N8: =IFERROR(VLOOKUP(L8,$H$5:$J$13,3,FALSE),0) -> 0 | P8: DFM | Q8: 0 | R8: 0 | V8: May | W8: 22 | X8: 28 | AC8: Jul | AD8: 28 | AF8: 26 | AG8: 6 | AS8: Jul | AT8: 28 | AU8: 26 | AV8: 26
C9: RFQ | D9: 67 | H9: PROJECT | I9: 6 | J9: 1 | L9: Internal DFM | M9: =IFERROR(VLOOKUP(L9,$H$5:$J$11,2,FALSE),0) -> 0 | N9: =IFERROR(VLOOKUP(L9,$H$5:$J$13,3,FALSE),0) -> 0 | P9: OTHER | Q9: 31 | R9: 0 | V9: Jun | W9: 24 | X9: 35 | AC9: Jan | AD9: 2 | AF9: 20 | AS9: Jan | AT9: 2 | AU9: 20 | AV9: 20
H10: RFQ | I10: 65 | J10: 2 | L10: PROJECT | M10: =IFERROR(VLOOKUP(L10,$H$5:$J$13,2,FALSE),0) -> 6 | N10: =IFERROR(VLOOKUP(L10,$H$5:$J$13,3,FALSE),0) -> 1 | P10: Internal DFM | Q10: 0 | R10: 0 | V10: Jun | W10: 25 | X10: 30 | AC10: Jan | AD10: 3 | AF10: 22 | AS10: Jan | AT10: 3 | AU10: 22 | AV10: 22
C11: PACKING | D11: 199 | I11: 1 | L11: MEETING | M11: =IFERROR(VLOOKUP(L11,$H$5:$J$13,2,FALSE),0) -> 75 | N11: =IFERROR(VLOOKUP(L11,$H$5:$J$13,3,FALSE),0) -> 0 | P11: MEETING | Q11: 75 | R11: 0 | V11: Jun | W11: 26 | X11: 24 | AC11: Jan | AD11: 4 | AF11: 26 | AS11: Jan | AT11: 4 | AU11: 26 | AV11: 26
C12: Part DFM | D12: 15 | H12: PACKING | I12: 197 | J12: 2 | L12: DFA | M12: =IFERROR(VLOOKUP(L12,$H$5:$J$11,2,FALSE),0) -> 20 | N12: =IFERROR(VLOOKUP(L12,$H$5:$J$13,3,FALSE),0) -> 0 | P12: DFA | Q12: 20 | R12: 0 | V12: Jun | W12: 27 | X12: 21 | AC12: Jan | AD12: 5 | AF12: 27 | AS12: Jan | AT12: 5 | AU12: 27 | AV12: 27
B13: other task | C13: DFM Mold | D13: 64 | G13: Weekly ratio | H13: Part DFM | I13: 15 | L13: PACKING | M13: =IFERROR(VLOOKUP(L13,$H$5:$J$13,2,FALSE),0) -> 197 | N13: =IFERROR(VLOOKUP(L13,$H$5:$J$13,3,FALSE),0) -> 2 | P13: {=_xlfn._xlws.SORT(L13:N13,3,-1)} -> PACKING | Q13: 197 | R13: 2 | V13: Jun | W13: 23 | X13: 23 | AC13: Feb | AD13: 7 | AF13: 25 | AS13: Feb | AT13: 7 | AU13: 25 | AV13: 25
H14: DFM Mold | I14: 64 | V14: Jul | W14: 27 | X14: 15 | AC14: Feb | AD14: 8 | AF14: 26 | AS14: Feb | AT14: 8 | AU14: 26 | AV14: 26
C15: Type | D15: RFQ | H15: Count of TASK | J15: ป้ายชื่อคอลัมน์ | V15: Jul | W15: 28 | X15: 26 | Y15: 6 | AC15: Feb | AD15: 6 | AF15: 17 | AS15: Feb | AT15: 6 | AU15: 17 | AV15: 17
H16: ป้ายชื่อแถว | I16: WW | J16: NPI | K16: MEETING | L16: OTHER | M16: DFA | N16: PROJECT | O16: RFQ | Q16: PACKING | R16: Part DFM | S16: DFM Mold | V16: Jan | W16: 2 | X16: 20 | AC16: Feb | AD16: 9 | AF16: 29 | AS16: Feb | AT16: 9 | AU16: 29 | AV16: 29
C17: ป้ายชื่อแถว | D17: Count of TASK | H17: May | J17: 4 | K17: 6 | L17: 1 | N17: 1 | O17: 9 | Q17: 46 | R17: 3 | S17: 39 | V17: Jan | W17: 3 | X17: 22 | AC17: Mar | AD17: 10 | AF17: 21 | AS17: Mar | AT17: 10 | AU17: 21 | AV17: 21
C18: RFQ | D18: 10 | H18: Jun | J18: 20 | K18: 19 | L18: 5 | M18: 8 | N18: 3 | O18: 12 | Q18: 52 | R18: 4 | S18: 9 | V18: Jan | W18: 4 | X18: 26 | AC18: Mar | AD18: 13 | AF18: 25 | AS18: Mar | AT18: 13 | AU18: 25 | AV18: 25
C19: RFQ Packing | D19: 57 | H19: Jul | I19: 27 | J19: 7 | K19: 3 | N19: 1 | O19: 1 | Q19: 2 | S19: 1 | V19: Jan | W19: 5 | X19: 27 | AC19: Mar | AD19: 11 | AF19: 36 | AS19: Mar | AT19: 11 | AU19: 36 | AV19: 36
H20: Jul | I20: 28 | J20: 6 | K20: 4 | M20: 2 | N20: 2 | O20: 4 | Q20: 11 | R20: 2 | S20: 1 | V20: Feb | W20: 7 | X20: 25 | AC20: Mar | AD20: 12 | AF20: 34 | AS20: Mar | AT20: 12 | AU20: 34 | AV20: 34
H21: Jan | I21: 2 | J21: 10 | K21: 3 | L21: 1 | O21: 1 | Q21: 5 | V21: Feb | W21: 8 | X21: 26 | AC21: Mar | AD21: 14 | AF21: 10 | AS21: Mar | AT21: 14 | AU21: 10 | AV21: 10
H22: Jan | I22: 3 | J22: 10 | K22: 2 | L22: 3 | O22: 3 | Q22: 3 | R22: 1 | V22: Feb | W22: 6 | X22: 17 | AC22: Apr | AD22: 17 | AF22: 21 | AS22: Apr | AT22: 17 | AU22: 21 | AV22: 21
H23: Jan | I23: 4 | J23: 4 | K23: 1 | L23: 1 | M23: 5 | O23: 1 | Q23: 9 | R23: 4 | S23: 1 | V23: Feb | W23: 9 | X23: 29 | AC23: Apr | AD23: 14 | AF23: 11 | AS23: Apr | AT23: 14 | AU23: 11 | AV23: 11
H24: Jan | I24: 5 | J24: 11 | K24: 3 | L24: 1 | M24: 1 | O24: 1 | Q24: 5 | S24: 5 | V24: Mar | W24: 10 | X24: 21 | AC24: Apr | AD24: 15 | AF24: 12 | AS24: Apr | AT24: 15 | AU24: 12 | AV24: 12
H25: Feb | I25: 7 | J25: 8 | K25: 2 | L25: 1 | M25: 1 | O25: 7 | Q25: 5 | S25: 1 | V25: Mar | W25: 13 | X25: 25 | AC25: Apr | AD25: 18 | AF25: 15 | AS25: Apr | AT25: 18 | AU25: 15 | AV25: 15
H26: Feb | I26: 8 | J26: 7 | K26: 4 | L26: 3 | M26: 1 | O26: 2 | Q26: 7 | S26: 2 | V26: Mar | W26: 11 | X26: 36 | AS26: ผลรวมทั้งหมด | AU26: 659 | AV26: 659
H27: Feb | I27: 6 | J27: 5 | K27: 2 | L27: 2 | O27: 2 | Q27: 5 | S27: 1 | V27: Mar | W27: 12 | X27: 34
H28: Feb | I28: 9 | J28: 19 | K28: 1 | L28: 1 | O28: 2 | Q28: 6 | V28: Mar | W28: 14 | X28: 10
H29: Mar | I29: 10 | J29: 8 | K29: 1 | L29: 7 | O29: 4 | Q29: 1 | V29: Apr | W29: 17 | X29: 21
H30: Mar | I30: 13 | J30: 15 | K30: 2 | L30: 1 | O30: 2 | Q30: 5 | V30: Apr | W30: 14 | X30: 11
H31: Mar | I31: 11 | J31: 12 | K31: 9 | L31: 2 | O31: 3 | Q31: 10 | V31: Apr | W31: 15 | X31: 12
H32: Mar | I32: 12 | J32: 22 | K32: 2 | M32: 1 | O32: 2 | Q32: 3 | S32: 4 | V32: Apr | W32: 18 | X32: 15
H33: Mar | I33: 14 | J33: 3 | K33: 3 | O33: 3 | Q33: 1
H34: Apr | I34: 17 | J34: 5 | K34: 1 | L34: 2 | O34: 2 | Q34: 10 | R34: 1
H35: Apr | I35: 14 | J35: 7 | K35: 1 | O35: 1 | Q35: 2
H36: Apr | I36: 15 | J36: 3 | K36: 6 | Q36: 3
H37: Apr | I37: 18 | J37: 1 | M37: 1 | O37: 5 | Q37: 8

Sheet Pivot
B1: Ratio | G1: Pending task | U1: Close vs open | AB1: Overdue | AS1: Status | AT1: Close
AK2: OverDue Aleart | AL2: (หลายรายการ)
C3: ป้ายชื่อแถว | D3: Count of TASK | H3: Count of Status | I3: ป้ายชื่อคอลัมน์ | P3: sort | V3: Count of Status | X3: ป้ายชื่อคอลัมน์ | AC3: Count of OverDue Aleart | AE3: ป้ายชื่อคอลัมน์ | AS3: Count of Performace status | AU3: ป้ายชื่อคอลัมน์ | AZ3: total | BA3: =GETPIVOTDATA("Performace",$AS$3) -> 659
C4: NPI | D4: 187 | H4: ป้ายชื่อแถว | I4: Close | J4: On process | L4: Type | M4: Close | N4: On process | P4: Type | Q4: Close | R4: On Process | V4: ป้ายชื่อแถว | W4: WW | X4: Close | Y4: On process | Z4: (ว่าง) | AC4: ป้ายชื่อแถว | AD4: WW | AE4: Overdue | AF4: Closed | AG4: On time | AH4: (ว่าง) | AK4: ป้ายชื่อแถว | AL4: Type | AM4: TASK | AN4: Target Date | AS4: ป้ายชื่อแถว | AT4: WW | AU4: On Time | AV4: ผลรวมทั้งหมด | AZ4: ontime | BA4: =GETPIVOTDATA("Performace",$AS$3,"Performace","On Time") -> 659 | BB4: =BA4/BA3 -> 1
C5: DFM Mold | D5: 64 | H5: DFM Mold | I5: 64 | L5: RFQ | M5: =IFERROR(VLOOKUP(L5,$H$5:$J$13,2,FALSE),0) -> 65 | N5: =IFERROR(VLOOKUP(L5,$H$5:$J$13,3,FALSE),0) -> 2 | P5: {=_xlfn._xlws.SORT(L5:N12,3,-1)} -> RFQ | Q5: 65 | R5: 2 | V5: May | W5: 19 | X5: 14 | AC5: May | AD5: 19 | AF5: 14 | AS5: May | AT5: 19 | AU5: 14 | AV5: 14 | AZ5: delay | BA5: =IFERROR(GETPIVOTDATA("Performace",$AS$3,"Performace","Delay"),0) -> 0 | BB5: =BA5/BA3 -> 0
C6: Part DFM | D6: 15 | H6: MEETING | I6: 75 | L6: NPI | M6: =IFERROR(VLOOKUP(L6,$H$5:$J$13,2,FALSE),0) -> 186 | N6: =IFERROR(VLOOKUP(L6,$H$5:$J$11,3,FALSE),0) -> 1 | P6: NPI | Q6: 186 | R6: 1 | V6: May | W6: 20 | X6: 28 | AC6: May | AD6: 20 | AF6: 28 | AS6: May | AT6: 20 | AU6: 28 | AV6: 28
C7: MEETING | D7: 75 | H7: NPI | I7: 186 | J7: 1 | L7: DFM Mold | M7: =IFERROR(VLOOKUP(L7,$H$5:$J$11,2,FALSE),0) -> 64 | N7: =IFERROR(VLOOKUP(L7,$H$5:$J$11,3,FALSE),0) -> 0 | P7: PROJECT | Q7: 6 | R7: 1 | V7: May | W7: 21 | X7: 39 | AC7: May | AD7: 21 | AF7: 39 | AS7: May | AT7: 21 | AU7: 39 | AV7: 39
C8: OTHER | D8: 31 | H8: OTHER | I8: 31 | L8: OTHER | M8: =IFERROR(VLOOKUP(L8,$H$5:$J$11,2,FALSE),0) -> 31 | N8: =IFERROR(VLOOKUP(L8,$H$5:$J$11,3,FALSE),0) -> 0 | P8: DFM Mold | Q8: 64 | R8: 0 | V8: May | W8: 22 | X8: 28 | AC8: May | AD8: 22 | AF8: 28 | AS8: May | AT8: 22 | AU8: 28 | AV8: 28
C9: DFA | D9: 20 | H9: DFA | I9: 20 | L9: Part DFM | M9: =IFERROR(VLOOKUP(L9,$H$5:$J$13,2,FALSE),0) -> 0 | N9: =IFERROR(VLOOKUP(L9,$H$5:$J$11,3,FALSE),0) -> 0 | P9: OTHER | Q9: 31 | R9: 0 | V9: Jun | W9: 24 | X9: 35 | AC9: Jun | AD9: 24 | AF9: 35 | AS9: Jun | AT9: 24 | AU9: 35 | AV9: 35
C10: PROJECT | D10: 7 | H10: PROJECT | I10: 6 | J10: 1 | L10: PROJECT | M10: =IFERROR(VLOOKUP(L10,$H$5:$J$13,2,FALSE),0) -> 6 | N10: =IFERROR(VLOOKUP(L10,$H$5:$J$11,3,FALSE),0) -> 1 | P10: Part DFM | Q10: 0 | R10: 0 | V10: Jun | W10: 25 | X10: 30 | AC10: Jun | AD10: 25 | AF10: 30 | AS10: Jun | AT10: 25 | AU10: 30 | AV10: 30
C11: RFQ | D11: 67 | H11: RFQ | I11: 65 | J11: 2 | L11: MEETING | M11: =IFERROR(VLOOKUP(L11,$H$5:$J$13,2,FALSE),0) -> 75 | N11: =IFERROR(VLOOKUP(L11,$H$5:$J$11,3,FALSE),0) -> 0 | P11: MEETING | Q11: 75 | R11: 0 | V11: Jun | W11: 26 | X11: 24 | AC11: Jun | AD11: 26 | AF11: 24 | AS11: Jun | AT11: 26 | AU11: 23 | AV11: 23
C12: PACKING | D12: 199 | H12: PACKING | I12: 197 | J12: 2 | L12: DFA | M12: =IFERROR(VLOOKUP(L12,$H$5:$J$13,2,FALSE),0) -> 20 | N12: =IFERROR(VLOOKUP(L12,$H$5:$J$11,3,FALSE),0) -> 0 | P12: DFA | Q12: 20 | R12: 0 | V12: Jun | W12: 27 | X12: 21 | AC12: Jun | AD12: 27 | AF12: 21 | AS12: Jun | AT12: 27 | AU12: 21 | AV12: 21
B13: other task | G13: Weekly ratio | L13: PACKING | M13: =IFERROR(VLOOKUP(L13,$H$5:$J$13,2,FALSE),0) -> 197 | N13: =IFERROR(VLOOKUP(L13,$H$5:$J$13,3,FALSE),0) -> 2 | P13: {=_xlfn._xlws.SORT(L13:N13,3,-1)} -> PACKING | Q13: 197 | R13: 2 | V13: Jun | W13: 23 | X13: 23 | AC13: Jun | AD13: 23 | AF13: 23 | AS13: Jun | AT13: 23 | AU13: 23 | AV13: 23
V14: Jul | W14: 27 | X14: 15 | AC14: Jul | AD14: 27 | AF14: 15 | AS14: Jul | AT14: 27 | AU14: 15 | AV14: 15
C15: Type | D15: OTHER | H15: Count of TASK | J15: ป้ายชื่อคอลัมน์ | V15: Jul | W15: 28 | X15: 26 | Y15: 6 | AC15: Jul | AD15: 28 | AF15: 26 | AG15: 6 | AS15: Jul | AT15: 28 | AU15: 26 | AV15: 26
H16: ป้ายชื่อแถว | I16: WW | J16: NPI | K16: MEETING | L16: OTHER | M16: DFA | N16: PROJECT | O16: RFQ | Q16: PACKING | R16: Part DFM | S16: DFM Mold | V16: Jan | W16: 2 | X16: 20 | AC16: Jan | AD16: 2 | AF16: 20 | AS16: Jan | AT16: 2 | AU16: 20 | AV16: 20
C17: ป้ายชื่อแถว | D17: Count of TASK | H17: May | I17: 19 | O17: 3 | Q17: 10 | S17: 1 | V17: Jan | W17: 3 | X17: 22 | AC17: Jan | AD17: 3 | AF17: 22 | AS17: Jan | AT17: 3 | AU17: 22 | AV17: 22
C18: Create standard document | D18: 2 | H18: May | I18: 20 | K18: 1 | O18: 2 | Q18: 2 | S18: 23 | V18: Jan | W18: 4 | X18: 26 | AC18: Jan | AD18: 4 | AF18: 26 | AS18: Jan | AT18: 4 | AU18: 26 | AV18: 26
C19: Training | D19: 20 | H19: May | I19: 21 | J19: 2 | K19: 3 | N19: 1 | O19: 2 | Q19: 22 | S19: 9 | V19: Jan | W19: 5 | X19: 27 | AC19: Jan | AD19: 5 | AF19: 27 | AS19: Jan | AT19: 5 | AU19: 27 | AV19: 27
C20: Interview candidate new member | D20: 1 | H20: May | I20: 22 | J20: 2 | K20: 2 | L20: 1 | O20: 2 | Q20: 12 | R20: 3 | S20: 6 | V20: Feb | W20: 7 | X20: 25 | AC20: Feb | AD20: 7 | AF20: 25 | AS20: Feb | AT20: 7 | AU20: 25 | AV20: 25
C21: 5S meeting | D21: 2 | H21: Jun | I21: 24 | J21: 5 | K21: 2 | L21: 1 | O21: 2 | Q21: 18 | R21: 1 | S21: 6 | V21: Feb | W21: 8 | X21: 26 | AC21: Feb | AD21: 8 | AF21: 26 | AS21: Feb | AT21: 8 | AU21: 26 | AV21: 26
C22: Support register document | D22: 1 | H22: Jun | I22: 25 | J22: 5 | K22: 5 | L22: 3 | M22: 1 | N22: 1 | O22: 2 | Q22: 10 | R22: 1 | S22: 2 | V22: Feb | W22: 6 | X22: 17 | AC22: Feb | AD22: 6 | AF22: 17 | AS22: Feb | AT22: 6 | AU22: 17 | AV22: 17
C23: Visit Exhibition | D23: 5 | H23: Jun | I23: 26 | J23: 1 | K23: 8 | L23: 1 | M23: 3 | N23: 2 | O23: 3 | Q23: 4 | R23: 1 | V23: Feb | W23: 9 | X23: 29 | AC23: Feb | AD23: 9 | AF23: 29 | AS23: Feb | AT23: 9 | AU23: 29 | AV23: 29
H24: Jun | I24: 27 | J24: 5 | K24: 2 | M24: 2 | O24: 2 | Q24: 9 | R24: 1 | V24: Mar | W24: 10 | X24: 21 | AC24: Mar | AD24: 10 | AF24: 21 | AS24: Mar | AT24: 10 | AU24: 21 | AV24: 21
H25: Jun | I25: 23 | J25: 4 | K25: 2 | M25: 2 | O25: 3 | Q25: 11 | S25: 1 | V25: Mar | W25: 13 | X25: 25 | AC25: Mar | AD25: 13 | AF25: 25 | AS25: Mar | AT25: 13 | AU25: 25 | AV25: 25
H26: Jul | I26: 27 | J26: 7 | K26: 3 | N26: 1 | O26: 1 | Q26: 2 | S26: 1 | V26: Mar | W26: 11 | X26: 36 | AC26: Mar | AD26: 11 | AF26: 36 | AS26: Mar | AT26: 11 | AU26: 36 | AV26: 36
H27: Jul | I27: 28 | J27: 6 | K27: 4 | M27: 2 | N27: 2 | O27: 4 | Q27: 11 | R27: 2 | S27: 1 | V27: Mar | W27: 12 | X27: 34 | AC27: Mar | AD27: 12 | AF27: 34 | AS27: Mar | AT27: 12 | AU27: 34 | AV27: 34
H28: Jan | I28: 2 | J28: 10 | K28: 3 | L28: 1 | O28: 1 | Q28: 5 | V28: Mar | W28: 14 | X28: 10 | AC28: Mar | AD28: 14 | AF28: 10 | AS28: Mar | AT28: 14 | AU28: 10 | AV28: 10
H29: Jan | I29: 3 | J29: 10 | K29: 2 | L29: 3 | O29: 3 | Q29: 3 | R29: 1 | V29: Apr | W29: 17 | X29: 21 | AC29: Apr | AD29: 17 | AF29: 21 | AS29: Apr | AT29: 17 | AU29: 21 | AV29: 21
H30: Jan | I30: 4 | J30: 4 | K30: 1 | L30: 1 | M30: 5 | O30: 1 | Q30: 9 | R30: 4 | S30: 1 | V30: Apr | W30: 14 | X30: 11 | AC30: Apr | AD30: 14 | AF30: 11 | AS30: Apr | AT30: 14 | AU30: 11 | AV30: 11
H31: Jan | I31: 5 | J31: 11 | K31: 3 | L31: 1 | M31: 1 | O31: 1 | Q31: 5 | S31: 5 | V31: Apr | W31: 15 | X31: 12 | AC31: Apr | AD31: 15 | AF31: 12 | AS31: Apr | AT31: 15 | AU31: 12 | AV31: 12
H32: Feb | I32: 7 | J32: 8 | K32: 2 | L32: 1 | M32: 1 | O32: 7 | Q32: 5 | S32: 1 | V32: Apr | W32: 18 | X32: 15 | AC32: Apr | AD32: 18 | AF32: 15 | AS32: Apr | AT32: 18 | AU32: 15 | AV32: 15
H33: Feb | I33: 8 | J33: 7 | K33: 4 | L33: 3 | M33: 1 | O33: 2 | Q33: 7 | S33: 2 | AS33: ผลรวมทั้งหมด | AU33: 659 | AV33: 659
H34: Feb | I34: 6 | J34: 5 | K34: 2 | L34: 2 | O34: 2 | Q34: 5 | S34: 1
C35: ป้ายชื่อแถว | H35: Feb | I35: 9 | J35: 19 | K35: 1 | L35: 1 | O35: 2 | Q35: 6
C36: All | H36: Mar | I36: 10 | J36: 8 | K36: 1 | L36: 7 | O36: 4 | Q36: 1
C37: Bunnarak | H37: Mar | I37: 13 | J37: 15 | K37: 2 | L37: 1 | O37: 2 | Q37: 5
C38: Thiti | H38: Mar | I38: 11 | J38: 12 | K38: 9 | L38: 2 | O38: 3 | Q38: 10
C39: Nattachai | H39: Mar | I39: 12 | J39: 22 | K39: 2 | M39: 1 | O39: 2 | Q39: 3 | S39: 4
C40: Chutiporn | H40: Mar | I40: 14 | J40: 3 | K40: 3 | O40: 3 | Q40: 1
...

Sheet Progress report
D9: PIC | E9: Task count | G9: Customer | H9: Task count
D10: Bunnarak | E10: =COUNTIF(Schedule2026!G13:G1232, D10) -> 133 | G10: Cat Power Design | H10: =COUNTIF(Schedule2026!F13:F1204, G10) -> 0
D11: Tae | E11: =COUNTIF(Schedule2026!G13:G1232, D11) -> 75 | G11: AEG | H11: =COUNTIF(Schedule2026!F13:F1218, G11) -> 14
D12: All | E12: =COUNTIF(Schedule2026!G24:G1232, D12) -> 2 | G12: Atlantic | H12: =COUNTIF(Schedule2026!F13:F1219, G12) -> 3
D13: Chutiporn | E13: =COUNTIF(Schedule2026!G13:G1232, D13) -> 81 | G13: Blue Wave Technologies | H13: =COUNTIF(Schedule2026!F13:F1220, G13) -> 0
D14: Thiti | E14: =COUNTIF(Schedule2026!G13:G1232, D14) -> 220 | G14: Enersys | H14: =COUNTIF(Schedule2026!F13:F1221, G14) -> 128
D15: Tea | E15: =COUNTIF(Schedule2026!G24:G1232, D15) -> 0 | G15: Fairland | H15: =COUNTIF(Schedule2026!F13:F1222, G15) -> 6
E16: =SUM(E10:E14) -> 511 | G16: IES | H16: =COUNTIF(Schedule2026!F13:F1223, G16) -> 22
G17: JRI | H17: =COUNTIF(Schedule2026!F13:F1224, G17) -> 102
G18: Leach | H18: =COUNTIF(Schedule2026!F13:F1225, G18) -> 13
G19: Maatel | H19: =COUNTIF(Schedule2026!F13:F1226, G19) -> 19
G20: Numworks | H20: =COUNTIF(Schedule2026!F13:F1227, G20) -> 126
G21: FONROCHE | H21: =COUNTIF(Schedule2026!F14:F1228, G21) -> 30
F290: Fonroche

Sheet Sheet6
